{
 "cells": [
  {
   "cell_type": "code",
   "execution_count": 2,
   "id": "fbad109f",
   "metadata": {},
   "outputs": [],
   "source": [
    "import pandas as pd\n",
    "import numpy as np\n",
    "import matplotlib.pyplot as plt\n",
    "%matplotlib inline\n",
    "import seaborn as sns"
   ]
  },
  {
   "cell_type": "code",
   "execution_count": 8,
   "id": "88a3adbb",
   "metadata": {},
   "outputs": [
    {
     "name": "stdout",
     "output_type": "stream",
     "text": [
      "Could not fetch URL https://pypi.org/simple/pandas-profiling/: There was a problem confirming the ssl certificate: HTTPSConnectionPool(host='pypi.org', port=443): Max retries exceeded with url: /simple/pandas-profiling/ (Caused by SSLError(SSLCertVerificationError(1, '[SSL: CERTIFICATE_VERIFY_FAILED] certificate verify failed: self signed certificate in certificate chain (_ssl.c:1129)'))) - skipping\n",
      "Could not fetch URL https://pypi.org/simple/pip/: There was a problem confirming the ssl certificate: HTTPSConnectionPool(host='pypi.org', port=443): Max retries exceeded with url: /simple/pip/ (Caused by SSLError(SSLCertVerificationError(1, '[SSL: CERTIFICATE_VERIFY_FAILED] certificate verify failed: self signed certificate in certificate chain (_ssl.c:1129)'))) - skipping\n",
      "Note: you may need to restart the kernel to use updated packages.\n"
     ]
    },
    {
     "name": "stderr",
     "output_type": "stream",
     "text": [
      "WARNING: Retrying (Retry(total=4, connect=None, read=None, redirect=None, status=None)) after connection broken by 'SSLError(SSLCertVerificationError(1, '[SSL: CERTIFICATE_VERIFY_FAILED] certificate verify failed: self signed certificate in certificate chain (_ssl.c:1129)'))': /simple/pandas-profiling/\n",
      "WARNING: Retrying (Retry(total=3, connect=None, read=None, redirect=None, status=None)) after connection broken by 'SSLError(SSLCertVerificationError(1, '[SSL: CERTIFICATE_VERIFY_FAILED] certificate verify failed: self signed certificate in certificate chain (_ssl.c:1129)'))': /simple/pandas-profiling/\n",
      "WARNING: Retrying (Retry(total=2, connect=None, read=None, redirect=None, status=None)) after connection broken by 'SSLError(SSLCertVerificationError(1, '[SSL: CERTIFICATE_VERIFY_FAILED] certificate verify failed: self signed certificate in certificate chain (_ssl.c:1129)'))': /simple/pandas-profiling/\n",
      "WARNING: Retrying (Retry(total=1, connect=None, read=None, redirect=None, status=None)) after connection broken by 'SSLError(SSLCertVerificationError(1, '[SSL: CERTIFICATE_VERIFY_FAILED] certificate verify failed: self signed certificate in certificate chain (_ssl.c:1129)'))': /simple/pandas-profiling/\n",
      "WARNING: Retrying (Retry(total=0, connect=None, read=None, redirect=None, status=None)) after connection broken by 'SSLError(SSLCertVerificationError(1, '[SSL: CERTIFICATE_VERIFY_FAILED] certificate verify failed: self signed certificate in certificate chain (_ssl.c:1129)'))': /simple/pandas-profiling/\n",
      "ERROR: Could not find a version that satisfies the requirement pandas-profiling (from versions: none)\n",
      "ERROR: No matching distribution found for pandas-profiling\n",
      "WARNING: There was an error checking the latest version of pip.\n"
     ]
    }
   ],
   "source": [
    "pip install pandas-profiling --user"
   ]
  },
  {
   "cell_type": "code",
   "execution_count": 6,
   "id": "5b0641bb",
   "metadata": {},
   "outputs": [
    {
     "ename": "ModuleNotFoundError",
     "evalue": "No module named 'pandas_profiling'",
     "output_type": "error",
     "traceback": [
      "\u001b[1;31m---------------------------------------------------------------------------\u001b[0m",
      "\u001b[1;31mModuleNotFoundError\u001b[0m                       Traceback (most recent call last)",
      "\u001b[1;32m~\\AppData\\Local\\Temp\\ipykernel_18700\\3468475291.py\u001b[0m in \u001b[0;36m<module>\u001b[1;34m\u001b[0m\n\u001b[1;32m----> 1\u001b[1;33m \u001b[1;32mimport\u001b[0m \u001b[0mpandas_profiling\u001b[0m \u001b[1;32mas\u001b[0m \u001b[0mpf\u001b[0m\u001b[1;33m\u001b[0m\u001b[1;33m\u001b[0m\u001b[0m\n\u001b[0m",
      "\u001b[1;31mModuleNotFoundError\u001b[0m: No module named 'pandas_profiling'"
     ]
    }
   ],
   "source": [
    "import pandas_profiling as pf"
   ]
  },
  {
   "cell_type": "code",
   "execution_count": 7,
   "id": "cec5f300",
   "metadata": {},
   "outputs": [
    {
     "ename": "SyntaxError",
     "evalue": "invalid syntax (1704432455.py, line 1)",
     "output_type": "error",
     "traceback": [
      "\u001b[1;36m  File \u001b[1;32m\"C:\\Users\\Sagar.Koktare\\AppData\\Local\\Temp\\ipykernel_18700\\1704432455.py\"\u001b[1;36m, line \u001b[1;32m1\u001b[0m\n\u001b[1;33m    pip3 install jupyter notebook\u001b[0m\n\u001b[1;37m         ^\u001b[0m\n\u001b[1;31mSyntaxError\u001b[0m\u001b[1;31m:\u001b[0m invalid syntax\n"
     ]
    }
   ],
   "source": []
  },
  {
   "cell_type": "code",
   "execution_count": null,
   "id": "c9ee7fe6",
   "metadata": {},
   "outputs": [],
   "source": []
  }
 ],
 "metadata": {
  "kernelspec": {
   "display_name": "Python 3 (ipykernel)",
   "language": "python",
   "name": "python3"
  },
  "language_info": {
   "codemirror_mode": {
    "name": "ipython",
    "version": 3
   },
   "file_extension": ".py",
   "mimetype": "text/x-python",
   "name": "python",
   "nbconvert_exporter": "python",
   "pygments_lexer": "ipython3",
   "version": "3.9.13"
  }
 },
 "nbformat": 4,
 "nbformat_minor": 5
}
